Workbook

Sheet DETALLE
B2: CONTROL INDIVIDUAL DE EXPEDIENTES ENERO 2024
B3: NO. | C3: INGRESO EXPEDIENTE | D3: EXPEDIENTE | E3: ANTECEDENTE | F3: PROPIETARIO SEGÚN SOLVENCIA | G3: DIRECCION SEGÚN SOLVENCIA | H3: ZONA | I3: COLONIA / CONDOMINIO | J3: NO. DE TELEFONO | K3: FECHA DE INSPECCIÓN | L3: FECHA ENTREGA PARA REVISION | M3: SE AUTORIZO | N3: UNIDADES FUNCIONALES | O3: NIVELES | P3: ANTIGUA/PLAN REG./POT | Q3: USO DE SUELO | R3: MT2 | S3: OBSERVACIONES | T3: PENDIENTE/NOTAS
B4: 1 | C4: 44278 | D4: RPNSR-560321 | F4: GLORIA ELIZABETH SANTOS LOPEZ | G4: CANTON XEPACHE | H4: R | I4: - | K4: 44417 | L4: 45295 | S4: REPORTE A JAM PARA REGULARIZACION
B5: 2 | C5: 45156 | D5: D-08-0099-2022 | F5: ANGELA OXLAJ ALVAREZ DE CHAN | G5: 4 CALLE 38-27 | H5: 8 | I5: - | K5: 45211 | L5: 45295 | S5: OFICIO A CATASTRO POR DESMEMBRACION
B6: 3 | C6: 44230 | D6: I-05-1138-2020 | F6: MARIA TERESA ALVARADO IXQUIACCHE | G6: DIAGONAL 15 | H6: 5 | I6: - | K6: - | L6: 45295 | S6: SE RETORNA A CATASTRO A PEDIDO DE LA INTERESADA
B7: 4 | C7: 45288 | D7: ANTN-O3-141223 | F7: JUAN VICTOR OLIVEROS RAMIREZ | G7: 22 AVENIDA 6-42A | H7: 3 | I7: - | K7: 44971 | L7: 45295 | S7: SE TRASLADA A SECRETARIA PARA FINALIZAR TRAMITE
B8: 5 | C8: 45211 | D8: RPNI1-020124 | F8: ILIANA VANESSA IXQUIAC MORALES | G8: CALLEJON 10A 19-15 | H8: 1 | I8: - | K8: 45233 | L8: 45302 | S8: REPORTE A JAM PARA REGULARIZACION
B9: 6 | C9: 45168 | D9: R-08-0158-2023 | F9: PABLO MACARIO PAXTOR | G9: F:96693 F:254 L:385 | H9: 8 | I9: - | K9: 45233 | L9: 45300 | S9: OFICIO A CATASTRO POR RECTIFICACION/CONST. ANTIGUA
B10: 7 | C10: 45041 | D10: RPNA5-030124 | F10: HENRY JACINTO AGUILAR RECINOS | G10: F:1215 F:215 L:343E | H10: 5 | I10: - | K10: 45233 | L10: 45302 | S10: REPORTE A JAM PARA REGULARIZACION
B11: 8 | C11: 45215 | D11: RPNL5-020124 | F11: WERNER ALEXANDER LOPEZ PEREZ | G11: F:3374 F:374 L:127E | H11: 5 | I11: VISTALVALLE | K11: 45243 | L11: 45302 | S11: REPORTE A JAM PARA REGULARIZACION
B12: 9 | C12: 45288 | D12: ANTN-E1-421223 | F12: JOSE ABELARDO ELIAS ALVAREZ | G12: DIAGONAL 14, 1-23 | H12: 1 | I12: - | K12: 45300 | L12: 45300 | S12: INFORME EXTERNO A IUSI PARA CARGAR CONSTRUCCION
B13: 10 | C13: 45280 | D13: R-04-0229-2023 | F13: MIGUEL ANGEL MENCHU GARCIA | G13: AV. EL CENIZAL 8-45 | H13: 4 | I13: - | K13: 45300 | L13: 45302 | S13: OFICIO A CATASTRO/ CONSTRUCCION ANTIGUA
B14: 11 | C14: - | D14: RPNM5-100323 | F14: LAURA PILAR MATUL LEMUS DE MERIDA | G14: 4 CALLE 14-52 | H14: 5 | I14: - | K14: - | L14: 45302 | S14: INFORME DE LICENCIA
B15: 12 | C15: 45294 | D15: DMNH3-010124 | F15: IRAYDA MARIELLA HERNANDEZ MORALES | G15: 8 CALLE 21-22 | H15: 3 | I15: - | K15: 45300 | L15: 45302 | S15: CALCULO DE LICENCIA PARA DEMOLICION
B16: 13 | C16: 18/08/2023 | D16: PENDIENTE | F16: MARCO ANTONIO TISTOJ PEREZ | G16: CANTON CHOQUI | H16: 11 | I16: - | K16: 45243
B17: 14 | C17: - | D17: RPNPR-030123 | F17: MARITZA CONSUELO LOPEZ FLORES DE PEREIRA | G17: CANTON CHITUX; F:278973 F:62 L:647 | H17: R | I17: - | K17: - | L17: 45302 | S17: INFORME DE LICENCIA
B18: 15
B19: 16
B20: 17 | C20: 45247 | D20: I-01-1032-2023 | E20: N/A | F20: MARCO ANTONIO CALVAC GUERRA | G20: DIAGONAL 11B; F:261006 F:106 L:590A | H20: 1 | I20: - | J20: 52525090 | K20: 45280 | M20: VIVIENDA UNIFAMILIAR | P20: ANTIGUA | Q20: RESIDENCIAL | R20: 66.84 | S20: ='INFORME '!#REF! -> #REF! | T20: N/A
B21: 18
B22: 19
B23: 20
B24: 21 | C24: ='INFORME '!#REF! -> #REF! | D24: ='INFORME '!#REF! -> #REF! | F24: ='INFORME '!#REF! -> #REF! | G24: ='INFORME '!#REF! -> #REF! | H24: ='INFORME '!#REF! -> #REF! | I24: ='INFORME '!#REF! -> #REF! | K24: ='INFORME '!#REF! -> #REF! | L24: ='INFORME '!#REF! -> #REF! | S24: ='INFORME '!#REF! -> #REF!
B25: 22 | C25: ='INFORME '!#REF! -> #REF! | D25: ='INFORME '!#REF! -> #REF! | F25: ='INFORME '!#REF! -> #REF! | G25: ='INFORME '!#REF! -> #REF! | H25: ='INFORME '!#REF! -> #REF! | I25: ='INFORME '!#REF! -> #REF! | K25: ='INFORME '!#REF! -> #REF! | L25: ='INFORME '!#REF! -> #REF! | S25: ='INFORME '!#REF! -> #REF!
B26: 23 | C26: ='INFORME '!#REF! -> #REF! | D26: ='INFORME '!#REF! -> #REF! | F26: ='INFORME '!#REF! -> #REF! | G26: ='INFORME '!#REF! -> #REF! | H26: ='INFORME '!#REF! -> #REF! | I26: ='INFORME '!#REF! -> #REF! | K26: ='INFORME '!#REF! -> #REF! | L26: ='INFORME '!#REF! -> #REF! | S26: ='INFORME '!#REF! -> #REF!
B27: 24 | C27: ='INFORME '!#REF! -> #REF! | D27: ='INFORME '!#REF! -> #REF! | F27: ='INFORME '!#REF! -> #REF! | G27: ='INFORME '!#REF! -> #REF! | H27: ='INFORME '!#REF! -> #REF! | I27: ='INFORME '!#REF! -> #REF! | K27: ='INFORME '!#REF! -> #REF! | L27: ='INFORME '!#REF! -> #REF! | S27: ='INFORME '!#REF! -> #REF!
B28: 25 | C28: ='INFORME '!#REF! -> #REF! | D28: ='INFORME '!#REF! -> #REF! | F28: ='INFORME '!#REF! -> #REF! | G28: ='INFORME '!#REF! -> #REF! | H28: ='INFORME '!#REF! -> #REF! | I28: ='INFORME '!#REF! -> #REF! | K28: ='INFORME '!#REF! -> #REF! | L28: ='INFORME '!#REF! -> #REF! | S28: ='INFORME '!#REF! -> #REF!
B29: 26 | C29: ='INFORME '!#REF! -> #REF! | D29: ='INFORME '!#REF! -> #REF! | F29: ='INFORME '!#REF! -> #REF! | G29: ='INFORME '!#REF! -> #REF! | H29: ='INFORME '!#REF! -> #REF! | I29: ='INFORME '!#REF! -> #REF! | K29: ='INFORME '!#REF! -> #REF! | L29: ='INFORME '!#REF! -> #REF! | S29: ='INFORME '!#REF! -> #REF!
B30: 27 | C30: ='INFORME '!#REF! -> #REF! | D30: ='INFORME '!#REF! -> #REF! | F30: ='INFORME '!#REF! -> #REF! | G30: ='INFORME '!#REF! -> #REF! | H30: ='INFORME '!#REF! -> #REF! | I30: ='INFORME '!#REF! -> #REF! | K30: ='INFORME '!#REF! -> #REF! | L30: ='INFORME '!#REF! -> #REF! | S30: ='INFORME '!#REF! -> #REF!
B31: 28 | C31: ='INFORME '!#REF! -> #REF! | D31: ='INFORME '!#REF! -> #REF! | F31: ='INFORME '!#REF! -> #REF! | G31: ='INFORME '!#REF! -> #REF! | H31: ='INFORME '!#REF! -> #REF! | I31: ='INFORME '!#REF! -> #REF! | K31: ='INFORME '!#REF! -> #REF! | L31: ='INFORME '!#REF! -> #REF! | S31: ='INFORME '!#REF! -> #REF!
B32: 29 | C32: ='INFORME '!#REF! -> #REF! | D32: ='INFORME '!#REF! -> #REF! | F32: ='INFORME '!#REF! -> #REF! | G32: ='INFORME '!#REF! -> #REF! | H32: ='INFORME '!#REF! -> #REF! | I32: ='INFORME '!#REF! -> #REF! | J32: 53753124 | K32: ='INFORME '!#REF! -> #REF! | L32: ='INFORME '!#REF! -> #REF! | S32: ='INFORME '!#REF! -> #REF!
B33: 30 | C33: ='INFORME '!#REF! -> #REF! | D33: ='INFORME '!#REF! -> #REF! | E33: QUE RETORNE DE OT | F33: ='INFORME '!#REF! -> #REF! | G33: ='INFORME '!#REF! -> #REF! | H33: ='INFORME '!#REF! -> #REF! | I33: ='INFORME '!#REF! -> #REF! | J33: 55096143 | K33: ='INFORME '!#REF! -> #REF! | L33: ='INFORME '!#REF! -> #REF! | P33: PLAN REGULADOR | Q33: RESIDENCIAL | S33: ='INFORME '!#REF! -> #REF! | T33: QUE RETORNE DE OT
B34: 31 | C34: ='INFORME '!#REF! -> #REF! | D34: ='INFORME '!#REF! -> #REF! | E34: N/A | F34: ='INFORME '!#REF! -> #REF! | G34: ='INFORME '!#REF! -> #REF! | H34: ='INFORME '!#REF! -> #REF! | I34: ='INFORME '!#REF! -> #REF! | J34: 52525090 | K34: ='INFORME '!#REF! -> #REF! | L34: ='INFORME '!#REF! -> #REF! | M34: VIVIENDA UNIFAMILIAR | P34: ANTIGUA | Q34: RESIDENCIAL | R34: 66.84 | S34: ='INFORME '!#REF! -> #REF! | T34: N/A
B35: 32 | C35: ='INFORME '!#REF! -> #REF! | D35: ='INFORME '!#REF! -> #REF! | E35: N/A | F35: ='INFORME '!#REF! -> #REF! | G35: ='INFORME '!#REF! -> #REF! | H35: ='INFORME '!#REF! -> #REF! | I35: ='INFORME '!#REF! -> #REF! | J35: 49554506 | K35: ='INFORME '!#REF! -> #REF! | L35: ='INFORME '!#REF! -> #REF! | M35: PENDIENTE | S35: ='INFORME '!#REF! -> #REF! | T35: CORRECCION DE CERTIFICACION DE INMUEBLE
B36: 33 | C36: ='INFORME '!#REF! -> #REF! | D36: ='INFORME '!#REF! -> #REF! | E36: N/A | F36: ='INFORME '!#REF! -> #REF! | G36: ='INFORME '!#REF! -> #REF! | H36: ='INFORME '!#REF! -> #REF! | I36: ='INFORME '!#REF! -> #REF! | J36: 44283342 | K36: ='INFORME '!#REF! -> #REF! | L36: ='INFORME '!#REF! -> #REF! | M36: PENDIENTE | S36: ='INFORME '!#REF! -> #REF! | T36: QUE RETORNE DE OT
B37: 34 | C37: ='INFORME '!#REF! -> #REF! | D37: ='INFORME '!#REF! -> #REF! | E37: N/A | F37: ='INFORME '!#REF! -> #REF! | G37: ='INFORME '!#REF! -> #REF! | H37: ='INFORME '!#REF! -> #REF! | I37: ='INFORME '!#REF! -> #REF! | J37: 38480721 | K37: ='INFORME '!#REF! -> #REF! | L37: ='INFORME '!#REF! -> #REF! | M37: AMPLIACION VIVIENDA BIFAMILIAR SEGUNDO NIVEL | O37: 2 | P37: REGULARIZACION POR POT | Q37: RESIDENCIAL | R37: 73.06 | S37: ='INFORME '!#REF! -> #REF! | T37: 1ER NIVEL ANTIGUO, SEGUNDO NIVEL POR PLAN REGULADOR
B38: 35 | C38: ='INFORME '!#REF! -> #REF! | D38: ='INFORME '!#REF! -> #REF! | E38: N/A | F38: ='INFORME '!#REF! -> #REF! | G38: ='INFORME '!#REF! -> #REF! | H38: ='INFORME '!#REF! -> #REF! | I38: ='INFORME '!#REF! -> #REF! | J38: 30087844 | K38: ='INFORME '!#REF! -> #REF! | L38: ='INFORME '!#REF! -> #REF! | M38: VIVIENDA UNIFAMILIAR 2 NIVELES | O38: 2 | P38: POT | Q38: RESIDENCIAL | R38: 103.12 | S38: ='INFORME '!#REF! -> #REF! | T38: N/A
B39: 36 | C39: ='INFORME '!#REF! -> #REF! | D39: ='INFORME '!#REF! -> #REF! | E39: N/A | F39: ='INFORME '!#REF! -> #REF! | G39: ='INFORME '!#REF! -> #REF! | H39: ='INFORME '!#REF! -> #REF! | I39: ='INFORME '!#REF! -> #REF! | J39: 43924538 | K39: ='INFORME '!#REF! -> #REF! | L39: ='INFORME '!#REF! -> #REF! | M39: VIVIENDA UNIFAMILIAR DOS NIVELES | O39: 2 | P39: ANTIGUA RURAL | Q39: RESIDENCIAL | R39: 117.9 | S39: ='INFORME '!#REF! -> #REF! | T39: N/A
B40: 37 | C40: ='INFORME '!#REF! -> #REF! | D40: ='INFORME '!#REF! -> #REF! | E40: N/A | F40: ='INFORME '!#REF! -> #REF! | G40: ='INFORME '!#REF! -> #REF! | H40: ='INFORME '!#REF! -> #REF! | I40: ='INFORME '!#REF! -> #REF! | J40: 59594766 | K40: ='INFORME '!#REF! -> #REF! | L40: ='INFORME '!#REF! -> #REF! | M40: VIVIENDA UNIFAMILIAR 1 NIVEL | O40: 1 | P40: POT | Q40: RESIDENCIAL | R40: 41.75 | S40: ='INFORME '!#REF! -> #REF! | T40: N/A
B41: 38 | C41: ='INFORME '!#REF! -> #REF! | D41: ='INFORME '!#REF! -> #REF! | E41: N/A | F41: ='INFORME '!#REF! -> #REF! | G41: ='INFORME '!#REF! -> #REF! | H41: ='INFORME '!#REF! -> #REF! | I41: ='INFORME '!#REF! -> #REF! | J41: 421615951 | K41: ='INFORME '!#REF! -> #REF! | L41: ='INFORME '!#REF! -> #REF! | M41: PAVIMENTACION SALIDA DE MAXI DESPENSA | O41: - | P41: POT | Q41: - | R41: 179.95 | S41: ='INFORME '!#REF! -> #REF! | T41: N/A
...

Sheet INFORME 
B3: CONTROL INDIVIDUAL DE EXPEDIENTES ABRIL 2026
B4: NO. | C4: INGRESO EXPEDIENTE | D4: EXPEDIENTE | E4: PROPIETARIO SEGÚN SOLVENCIA | F4: DIRECCION SEGÚN SOLVENCIA | G4: ZONA | H4: COLONIA / CONDOMINIO | I4: FECHA DE INSPECCIÓN | J4: FECHA DE TRABAJO | K4: OBSERVACIONES O NOTAS IMPORTANTES
B5: 1 | C5: 46049 | D5: I-RCA80-2025-2025 | E5: OROZCO GOMEZ, MATEO | F5: CHUICAVIOC | I5: 46027 | J5: 46133 | K5: OFICIO CATASTRO | Q5: OFICIO CATÁSTRO
B6: =B5+1 -> 2 | C6: 46049 | D6: I-RCA80-2042-2025 | E6: LOPEZ LOPEZ, MAYRA LETICIA | F6: CHUICAVIOC | I6: 46027 | J6: 46133 | K6: OFICIO CATASTRO | Q6: OFICIO CATÁSTRO
B7: =B6+1 -> 3 | C7: 46049 | D7: I-RCA80-1944-2025 | E7: OROZCO GOMEZ, HENRY SAMUEL | F7: CHUICAVIOC | I7: 46027 | J7: 46133 | K7: OFICIO CATASTRO | Q7: OFICIO CATÁSTRO
B8: =B7+1 -> 4 | C8: 46049 | D8: I-RCA80-2043-2025 | E8: MORALES, MARIA WENDY COYOY CAHUEX DE | F8: CHUICAVIOC | I8: 46027 | J8: 46133 | K8: OFICIO CATASTRO | Q8: INFORME INTERNO SECRETARIA CONSTRUCCION ANTIGUA
B9: =B8+1 -> 5 | C9: 46049 | D9: I-RCA80-1948-2025 | E9: OROZCO, CANDIDO ELOY | F9: CHUICAVIOC | I9: 46027 | J9: 46133 | K9: OFICIO CATASTRO | Q9: LICENCIA DE OBRA
B10: =B9+1 -> 6 | C10: 46086 | D10: VUNF5-630326 | E10: FLORES DE LEON, CLAUDIA EUGENIA | F10: 10 AVENIDA A 15C-02 LOTE 1 MZ G | I10: 46107 | J10: 46136 | K10: LICENCIA DE OBRA | Q10: PROVIDENCIA A JUZGADOS POR CARGA SOBRE MARQ.
B11: =B10+1 -> 7 | C11: 46106 | D11: RPNT3-4060426 | E11: TAHAY HERNANDEZ CARMEN | F11: 7 CALLE 23-19 ZONA3 | I11: 46133 | J11: 46139 | K11: REGULARIZACION DE OBRA | Q11: LICENCIA DE OBRA
B12: =B11+1 -> 8 | C12: 46128 | D12: VUNC11-1080426 | E12: CIFUENTES MACARIO, MARIA CANDIDA LETICIA | F12: 6 CALLE 4-19 LOTE 25 FASE 2 | I12: 46135 | J12: 46140 | K12: LICENCIA DE OBRA | Q12: INFORME INTERNO SECRETARIA CONSTRUCCION ANTIGUA
B13: =B12+1 -> 9 | C13: 46135 | D13: VUNC8-1090426 | E13: CELIS, LUCIA FERNANDA MORALES CIFUENTES DE Y CONDUEÑO | F13: 34 AVENIDA A 0-86 | I13: 46135 | J13: 46140 | K13: LICENCIA DE OBRA | Q13: INFORME INTERNO SECRETARIA CONSTRUCCION ANTIGUA
B14: =B13+1 -> 10 | Q14: OFICIO A CATASTRO POR REGULARIZACION
B15: =B14+1 -> 11 | Q15: INFORME DE LICENCIA
B16: =B15+1 -> 12 | Q16: OFICIO A CATASTRO POR REGULARIZACION
B17: =B16+1 -> 13 | Q17: PROVIDENCIA A GESTION DE RIESGOS POR TALUD DE MURO
B18: =B17+1 -> 14 | Q18: PROVIDENCIA A OT POR USO DE SUELO, ALINEACION, CARGA URBANISTICA
B19: =B18+1 -> 15 | Q19: LICENCIA DE OBRA
B20: =B19+1 -> 16 | Q20: OFICIO A CATASTRO POR REGULARIZACION
B21: =B20+1 -> 17 | Q21: OFICIO A CATASTRO POR REGULARIZACION
B22: =B21+1 -> 18 | Q22: OFICIO A CATASTRO POR CONSTRUCCION INFORMAL
B23: =B22+1 -> 19 | Q23: INFORME DE LICENCIA
B24: =B23+1 -> 20 | Q24: REGULARIZACION DE OBRA/SE ENVIO COPIA A JUZGADO
B25: =B24+1 -> 21 | Q25: PROVIDENCIA A OT POR ALINEACION MUNICIPAL
... B27: =B26+1 -> 23 | Q27: INFORME AL VECINO PARA REQUISTOS DE REGULARIZACION
B28: =#REF!+1 -> #REF!
B29: =B28+1 -> #REF!
B30: TOTAL DE EXPEDIENTES TRABAJADOS | F30: 9 EXPEDIENTES
B34: CONTROL INDIVIDUAL DE EXPEDIENTES MAYO 2026
B35: NO. | C35: INGRESO EXPEDIENTE | D35: EXPEDIENTE | E35: PROPIETARIO SEGÚN SOLVENCIA | F35: DIRECCION SEGÚN SOLVENCIA | G35: ZONA | H35: COLONIA / CONDOMINIO | I35: FECHA DE INSPECCIÓN | K35: OBSERVACIONES O NOTAS IMPORTANTES
B36: 1 | C36: 46129 | D36: RPNC1-4240426 | E36: CAJAS ITZEP, RAFAEL SALVADOR | F36: 8va AVENIDA 0-10, ZONA 1 | G36: 1 | H36: - | I36: 46135 | J36: 46146 | K36: REGULARIZACIÓN
B37: =B36+1 -> 2 | C37: 46105 | D37: CRUPR-810326 | E37: PEREZ Y PEREZ, MARIA ANA | F37: CANTON CHUILAJU | G37: 5 | H37: - | I37: 46129 | J37: 46146 | K37: CONSTRUCCION RURAL
B38: =B37+1 -> 3 | C38: 46128 | D38: VUNDR-1310426 | E38: DESARROLLOS DE SUR-OCCIDENTE S.A. | F38: LOTE E24 SECTOR 1 CIUDAD VERDE CHICHIGUITAN | I38: 46140 | J38: 46146 | K38: REGULARIZACIÓN
B39: =B38+1 -> 4 | C39: 46142 | D39: VUNC1-1430526 | E39: CHO SAC, AROLDO RUBEN | F39: ZONA 1 DIAGONAL 11 26-15 | G39: 5 | H39: - | I39: 46148 | J39: 46147 | K39: REGULARIZACIÓN
B40: =B39+1 -> 5 | C40: 46128 | D40: VUNDR-1370426 | E40: DESARROLLOS DE SUR-OCCIDENTE S.A. | F40: LOTE E17 SECTOR 1 CIUDAD VERDE CHICHIGUITAN | G40: 1 | H40: - | I40: 46140 | J40: 46147 | K40: REGULARIZACIÓN
B41: =B40+1 -> 6 | C41: 46128 | D41: VUNDR-1360426 | E41: DESARROLLOS DE SUR-OCCIDENTE S.A. | F41: LOTE E29 SECTOR 1 CIUDAD VERDE CHICHIGUITAN | G41: 10 | H41: - | I41: 46140 | J41: 46147 | K41: REGULARIZACIÓN
B42: =B41+1 -> 7 | C42: 46128 | D42: VUNDR-1350426 | E42: DESARROLLOS DE SUR-OCCIDENTE S.A. | F42: LOTE E28 SECTOR 1 CIUDAD VERDE CHICHIGUITAN | G42: 3 | H42: - | I42: 46140 | J42: 46147 | K42: REGULARIZACIÓN
B43: =B42+1 -> 8 | C43: 46128 | D43: VUNDR-1340426 | E43: DESARROLLOS DE SUR-OCCIDENTE S.A. | F43: LOTE E27 SECTOR 1 CIUDAD VERDE CHICHIGUITAN | G43: 5 | H43: LA COLINA | I43: 46140 | J43: 46147 | K43: REGULARIZACIÓN
B44: =B43+1 -> 9 | C44: 46128 | D44: VUNDR-1330426 | E44: DESARROLLOS DE SUR-OCCIDENTE S.A. | F44: LOTE E26 SECTOR 1 CIUDAD VERDE CHICHIGUITAN | G44: 6 | H44: - | I44: 46140 | J44: 46147 | K44: REGULARIZACIÓN
B45: =B44+1 -> 10 | C45: 46128 | D45: VUNDR-1320426 | E45: DESARROLLOS DE SUR-OCCIDENTE S.A. | F45: LOTE E25 SECTOR 1 CIUDAD VERDE CHICHIGUITAN | I45: 46140 | J45: 46147 | K45: REGULARIZACIÓN
B46: =B45+1 -> 11 | C46: 45936 | D46: RPNA12-4430526 | E46: Ajsivinac Soberanis, Hilda María | F46: 6ta calle 12-158, sector 2 | G46: R | H46: - | I46: 46141 | J46: 46148 | K46: VUN SE PASO A RP, REINSPECCION
...

Sheet Hoja1
B3: CONTROL INDIVIDUAL DE EXPEDIENTES
B4: NO. | C4: EXPEDIENTE | D4: PROPIETARIO SEGÚN SOLVENCIA | E4: ZONA | F4: COLONIA / CONDOMINIO | G4: FECHA ENTREGA PARA REVISION | H4: OBSERVACIONES O NOTAS IMPORTANTES
B5: 1 | C5: RPNS1-190324 | D5: KARIN YANETH SAJ MORTAYA | E5: 1 | F5: - | G5: 45334 | H5: EN ESPERA DE CERTIFICACION DE INMUEBLE
B6: =B5+1 -> 2 | C6: RPNG1-170124 | D6: ALBERTO DAMIAN GUERRA MARIN | E6: R | F6: PLANES DEL PINAL | G6: 45322 | H6: EN ESPERA DE CERTIFICACION DE INMUEBLE
B7: =B6+1 -> 3 | C7: RPNI1-020124 | D7: ILIANA VANESSA IXQUIAC MORALES | E7: R | F7: NUEVA JERUSALEM | G7: 45322 | H7: EN ESPERA DE CERTIFICACION DE INMUEBLE
B8: =B7+1 -> 4 | C8: RPNG2-100322 | D8: JUAN JOSE GARCIA GARCIA Y CONDUEÑO | E8: 5 | F8: XELAGARDENS | G8: 45322 | H8: EN ESPERA DE CERTIFICACION DE INMUEBLE
B9: =B8+1 -> 5 | C9: RPNH1-200324 | D9: SILIVIA JUDITH HERNANDEZ LOPEZ | E9: 1 | F9: - | G9: 45323 | H9: EN ESPERA DE CERTIFICACION DE INMUEBLE
B10: =B9+1 -> 6 | C10: USNH3-310725 | D10: FREDY SON HASTEDT | E10: 9 | F10: - | G10: 45327 | H10: EN ESPERA DE CERTIFICACION DE INMUEBLE
B11: =B10+1 -> 7 | C11: ANTNH3-1910725 | D11: FREDY SON HASTEDT | E11: 1 | F11: - | G11: 45327 | H11: EN ESPERA DE CERTIFICACION DE INMUEBLE
B12: =B11+1 -> 8 | C12: USNH3-300725 | D12: FREDY SON HASTEDT | E12: 7 | F12: LOS TRIGALES | G12: 45327 | H12: EN ESPERA DE CERTIFICACION DE INMUEBLE
B13: =B12+1 -> 9 | C13: RPNH3-4120725 | D13: FREDY SON HASTEDT | E13: 1 | F13: - | G13: 45327 | H13: EN ESPERA DE CERTIFICACION DE INMUEBLE
B14: =B13+1 -> 10 | C14: RPNH3-4100725 | D14: FREDY SON HASTEDT | E14: 4 | F14: - | G14: 45327 | H14: EN ESPERA DE CERTIFICACION DE INMUEBLE
B15: =B14+1 -> 11 | C15: RPNR3-100324 | D15: MARY YOLANDA RODAS HERRERA | E15: R | F15: XELAGARDENS | G15: 45328 | H15: EN ESPERA DE CERTIFICACION DE INMUEBLE
B16: =B15+1 -> 12 | C16: RPNH3-540225 | D16: FREDY SON HASTEDT | E16: R | F16: - | G16: 45328 | H16: EN ESPERA DE CERTIFICACION DE INMUEBLE
B17: =B16+1 -> 13 | C17: RPNG5-080124 | D17: EFRAIN AVELINO GIRON BARRIOS | E17: 3 | F17: - | G17: 45338 | H17: EN ESPERA DE CERTIFICACION DE INMUEBLE
B18: =B17+1 -> 14 | C18: RPNB6-170424 | D18: RENE FRANCISCO BARRENO BARRENO | E18: 5 | F18: LAS CALAS | G18: 45334 | H18: EN ESPERA DE CERTIFICACION DE INMUEBLE
B19: =B18+1 -> 15 | C19: RPND7-341123 | D19: YORDAN HERALDO DE LA CRUZ MEJIA | E19: R | F19: - | G19: 45334 | H19: EN ESPERA DE CERTIFICACION DE INMUEBLE
B20: =B19+1 -> 16 | C20: RPND7-060224 | D20: ORIEL HUSAI DIAZ GRAMAJO | E20: 3 | F20: - | G20: 45334 | H20: EN ESPERA DE CERTIFICACION DE INMUEBLE
B21: =B20+1 -> 17 | C21: RPNJ8-080823 | D21: EDGAR ALFREDO ORTIZ LOPEZ | E21: 10 | F21: - | G21: 45334 | H21: EN ESPERA DE CERTIFICACION DE INMUEBLE
B22: =B21+1 -> 18 | C22: RPNR8-551023 | D22: JORGE MARIO RODAS LOPEZ | E22: R | F22: - | G22: 45334 | H22: EN ESPERA DE CERTIFICACION DE INMUEBLE
B23: =B22+1 -> 19 | C23: RPNH10-210224 | D23: JUAN FERNANDO MOISES HERNANDEZ QUIJ | E23: 5 | F23: LA COLINA | G23: 45334 | H23: EN ESPERA DE CERTIFICACION DE INMUEBLE
B24: =B23+1 -> 20 | C24: RPNT11-240823 | D24: SARA CELESTINA CAYAX TORRES DE TORRES | E24: 8 | F24: - | G24: 45334 | H24: EN ESPERA DE CERTIFICACION DE INMUEBLE
B25: =B24+1 -> 21 | C25: RPNLR-290124 | D25: JUANA LOPEZ LOPEZ | E25: 10 | F25: - | G25: 45338 | H25: EN ESPERA DE CERTIFICACION DE INMUEBLE
B26: =B25+1 -> 22 | C26: RPNL1-1690325 | D26: LAURA HILDA LOPEZ DE COJOM HUITZ | E26: 8 | F26: - | G26: 45338 | H26: EN ESPERA DE CERTIFICACION DE INMUEBLE
B27: 23 | C27: RPNCR-050123 | D27: VITALINO CRUZ CAHUEX | E27: 1 | F27: - | G27: 45338 | H27: EN ESPERA DE CERTIFICACION DE INMUEBLE
B28: =B27+1 -> 24 | C28: RPNP10-521023 | D28: BASILIO POZ PEREZ | H28: EN ESPERA DE CERTIFICACION DE INMUEBLE
B29: 25 | C29: VUNCR-010524 | D29: HUGO ARIEL CASTILLO PORTO | E29: 8 | F29: SANTA VIRGINIA | G29: 45338 | H29: SE DEBE ESPERAR EL CAMBIO DE USO DE SUELO.
B30: =B29+1 -> 26 | C30: R-13-0196-2024 | D30: ANA LUISA DIAZ MEJIA | E30: 7 | F30: - | G30: 45338 | H30: FALTA QUE EL PAGO PARA TRASLADARLO A DEPENDENCIA.
B31: =B30+1 -> 27 | C31: I-RCA80-1962-2025 | D31: PEDRO ROBERTO CRUZ OROZCO | H31: FALTA QUE EL PAGO PARA TRASLADARLO A DEPENDENCIA.
B32: =B31+1 -> 28 | C32: I-RCA80-1959-2025 | D32: MARIA THELMA COYOY CRUZ DE CAHUEX | H32: FALTA QUE EL PAGO PARA TRASLADARLO A DEPENDENCIA.
B33: =B32+1 -> 29 | C33: I-RCA80-1963-2025 | D33: JUAN RAMON AGUSTIN COYOY | H33: FALTA QUE EL PAGO PARA TRASLADARLO A DEPENDENCIA.
B34: =B33+1 -> 30 | C34: I-RCA80-1965-2025 | D34: NELSON ELIAS MACARIO CRUZ | H34: FALTA QUE EL PAGO PARA TRASLADARLO A DEPENDENCIA.
B35: =B34+1 -> 31 | C35: I-RCA80-1960-2025 | D35: JUANA CAHUEX CRUZ | H35: FALTA QUE EL PAGO PARA TRASLADARLO A DEPENDENCIA.
B36: =B35+1 -> 32 | C36: I-RCA80-1957-2025 | D36: CANDELARIA OROZCO COYOY DE CUPIL | H36: FALTA QUE EL PAGO PARA TRASLADARLO A DEPENDENCIA.
B37: =B36+1 -> 33 | C37: I-RCA80-1956-2025 | D37: MIRIAM MARLENY CUPIL OROZCO | H37: FALTA QUE EL PAGO PARA TRASLADARLO A DEPENDENCIA.
B38: =B37+1 -> 34 | C38: i-RCA80-1961-2025 | D38: EUSEBIA LOPEZ GOMEZ DE CRUZ | H38: FALTA QUE EL PAGO PARA TRASLADARLO A DEPENDENCIA.
B39: =B38+1 -> 35 | C39: I-RCA80-1964-2025 | D39: LUIS ALFONSO COYOY OROZCO | H39: FALTA QUE EL PAGO PARA TRASLADARLO A DEPENDENCIA.
B40: =B39+1 -> 36 | C40: I-RCA80-2050-2025 | D40: HEIDY ESMERALDA ESTACUY OROZCO | H40: FALTA QUE EL PAGO PARA TRASLADARLO A DEPENDENCIA.
B41: =B40+1 -> 37 | C41: I-RCA80-1955-2025 | D41: ALEX GABINO COYOY COTOM | H41: FALTA QUE EL PAGO PARA TRASLADARLO A DEPENDENCIA.
B42: TOTAL DE EXPEDIENTES TRABAJADOS | E42: 37 EXPEDIENTES

Sheet INSP_
B3: CONTROL INDIVIDUAL DE INSPECCIONES ABRIL 2024
B4: NO. | C4: INGRESO EXPEDIENTE | D4: EXPEDIENTE | E4: PROPIETARIO SEGÚN SOLVENCIA | F4: DIRECCION SEGÚN SOLVENCIA | G4: ZONA | H4: COLONIA / CONDOMINIO | I4: TELEFONO | J4: FECHA DE INSPECCION
B5: 1 | C5: 45225 | D5: RPNT3-4060426 | E5: TAHAY HERNANDEZ CARMEN | F5: 7 CALLE 23-19 | G5: 3 | J5: 46133
B6: 2 | C6: 45230 | D6: VUNC11-1080426 | E6: CIFUENTES MACARIO, MARIA CANDIDA LETICIA | F6: 6 CALLE 4-19 LOTE 25 FASE 2 | J6: 46135
B7: 3 | C7: 45216 | D7: VUNC8-1090426 | E7: CELIS, LUCIA FERNANDA MORALES CIFUENTES DE Y CONDUEÑO | F7: 34 AVENIDA A 0-86 | J7: 46135
B8: 4 | C8: 45216 | D8: RPNC1-4240426 | E8: CAJAS ITZEP, RAFAEL SALVADOR | F8: 8va AVENIDA 0-10 | G8: 1 | J8: 46135
B9: 5 | C9: 45196 | D9: CRUPR-810326 | E9: PEREZ Y PEREZ, MARIA ANA | F9: CANTON CHUILAJU | J9: 46135
B10: 6 | C10: 45175 | D10: VUNDR-1310426 | E10: DESARROLLOS DE SUR-OCCIDENTE S.A. | F10: LOTE E24 SECTOR 1 CIUDAD VERDE CHICHIGUITAN | J10: 46140
B11: 7 | C11: 45232 | D11: VUNDR-1320427 | E11: DESARROLLOS DE SUR-OCCIDENTE S.A. | F11: LOTE E25 SECTOR 1 CIUDAD VERDE CHICHIGUITAN | J11: 46140
B12: 8 | C12: 45133 | D12: VUNDR-1330428 | E12: DESARROLLOS DE SUR-OCCIDENTE S.A. | F12: LOTE E26 SECTOR 1 CIUDAD VERDE CHICHIGUITAN | J12: 46140
B13: 9 | C13: 45166 | D13: VUNDR-1340429 | E13: DESARROLLOS DE SUR-OCCIDENTE S.A. | F13: LOTE E27 SECTOR 1 CIUDAD VERDE CHICHIGUITAN | J13: 46140
B14: 10 | C14: 45167 | D14: VUNDR-1350430 | E14: DESARROLLOS DE SUR-OCCIDENTE S.A. | F14: LOTE E28 SECTOR 1 CIUDAD VERDE CHICHIGUITAN | J14: 46140
B15: 11 | D15: VUNDR-1360431 | E15: DESARROLLOS DE SUR-OCCIDENTE S.A. | F15: LOTE E29 SECTOR 1 CIUDAD VERDE CHICHIGUITAN | J15: 46140
B16: 12 | D16: VUNDR-1370432 | E16: DESARROLLOS DE SUR-OCCIDENTE S.A. | F16: LOTE E30 SECTOR 1 CIUDAD VERDE CHICHIGUITAN | J16: 46140
B17: 13 | D17: RPNO10-3850426 | E17: ORDOÑEZ VASQUEZ, DIEGO | F17: 5 AVENIDA 4-33, INTERIOR | J17: 46141
B18: 14 | D18: VUNSR-1130426 | E18: SANCHEZ, MARIA HERLINDA LOPEZ SACALXOT DE | F18: CANTON TIERRA COLORADA BAJA | J18: 46141
B19: 15 | D19: R-05-0055-2026 | E19: NAINSO GUAYMER HERNANDEZ VÁZQUES | F19: ZONA 5 | J19: 46141
B20: 16 | D20: VUNA12-3301025 | E20: AJSIVINAC SOBERANIS HILDA MARIA | F20: 6 CALLE 12-158 SECTOR 2 | J20: 46141
B21: 17
B22: 18
B23: 19
B24: 20
B25: 21
B26: 22
B27: 23
B28: 24
B29: 25
B30: 26
B32: 27
B33: 28
... B42: 37
B43: =B42+1 -> 38
B44: =B43+1 -> 39
B45: =B44+1 -> 40
B46: INSPECCIONES REALIZADAS | F46: 16 INSPECCIONES
B49: CONTROL INDIVIDUAL DE INSPECCIONES MAYO 2026
B50: NO. | C50: INGRESO EXPEDIENTE | D50: EXPEDIENTE | E50: PROPIETARIO SEGÚN SOLVENCIA | F50: DIRECCION SEGÚN SOLVENCIA | G50: ZONA | H50: COLONIA / CONDOMINIO | I50: TELEFONO | J50: FECHA DE INSPECCION
B51: 1 | C51: 45225 | D51: R-12-0052-2026 a RPNM12-4520526 | E51: JUAN MORALES ROMERO | F51: 9 CALLE LOTE #250 MANZANA "K" | G51: 12 | J51: 46147
B52: 2 | C52: 45230 | D52: R-03-0023-2026 | E52: LUZ MARIA DEL ROSARIO MIGEZ AGUILAR DE LAM | F52: 5 CALLE 14-14 | G52: 3 | J52: 46147
B53: 3 | C53: 45216 | D53: D-01-0113-2025 a RPNC1-4500526 | E53: JUANA ANIBAL MACHIC LOPEZ | F53: 5 AV. 11-44 | G53: 1 | J53: 46147
...

Sheet LICENCIAS
B2: LICENCIAS
B4: DE OBRA
B5: LICENCIA DE OBRA | C5: LICENCIA DE SUELO | D5: FECHA | E5: EXPEDIENTE | F5: NOMBRE | G5: DIRECCION | H5: DESTINO AUTORIZADO | I5: NIVELES | J5: UNIDADES EXISTENTES | K5: UNIDADES DE LA LICENCIA | L5: AÑO DE CONSTRUCCION | M5: OBSERVACIONES/CONSTRUCCION
B6: - | C6: 1 | E6: CRUCR-060126 | F6: VITALINO CRUZ CAHUEX | G6: CANTON CHUICAVIOC | H6: VIVIENDA UNIFAMILIAR | I6: 1 | J6: 0 | K6: 1 | L6: ANTIGUA | M6: DE 39.34
B7: 1 | C7: - | E7: RPNS5-020121 | F7: SHEILA YANIRA SANTIZO GONZALEZ | G7: 14 CALLE C0-20 ZONA 5 | H7: VIVIENDA UNIFAMILIAR
B8: 2 | C8: 2 | E8: RPNS5-630821 | F8: JULIA SAJCHE | G8: 1 AVENIDA 1-32 LOTE 39 MZ A ZONA 5
B9: 3 | C9: 3 | E9: RPNCR-1420226 | F9: MARIA EULOGIA CHICHCE CRUZ | G9: CANTON CHUICAVIOC | H9: VIVIENDA UNIFAMILIAR | I9: 2 | J9: 0 | K9: 1 | L9: POT | M9: DE MARIA PORRES, 373.41
B10: - | C10: 4 | E10: CRUCR-460226 | F10: ALEX GABINO, COYOY COTOM | G10: CANTON CHUICAVIOC | H10: VIVIENDA UNIFAMILIAR | I10: 1 | K10: 1 | L10: RURAL | M10: 254.04
B11: - | C11: 5 | E11: CRUCR-470226 | F11: EUSEBIA LOPEZ GOMEZ DE CRUZ} | G11: CANTON CHUICAVIOC | H11: VIVIENDA UNIFAMILIAR | I11: 1 | K11: 1 | L11: RURAL | M11: 301.22
B12: - | C12: 6 | E12: INFER-210226 | F12: HEIDY ESMERALDA ESTACUY OROZCO | G12: CANTON CHUICAVIOC | H12: VIVIENDA UNIFAMILIAR | I12: 1 | K12: 1 | L12: INFORMAL | M12: 20
B13: - | C13: 7 | E13: CRUCR-4990226 | F13: LUIS ALFONSO COYOY OROZCO | G13: CANTON CHUICAVIOC | H13: VIVIENDA UNIFAMILIAR | I13: 1 | K13: 1 | L13: RURAL | M13: 177.71
B14: 8 | C14: 8 | E14: RPNMR-1810226 | F14: NELSON ELIAS MACARIO CRUZ | G14: CANTON CHUICAVIOC | H14: VIVIENDA UNIFAMILIAR | I14: 1 | K14: 1 | L14: REGULARIZACION | M14: POT- 135.07
B15: 9 | C15: 9 | E15: rpncr-1830226 | F15: MIRIAM MARLENY CUPIL OROZCO | G15: CANTON CHUICAVIOC | H15: VIVIENDA UNIFAMILIAR | I15: 1 | K15: 1 | L15: REGULARIZACION | M15: POT-36.89
B16: 10 | C16: 10 | E16: RPNCR-1820226 | F16: CANDELARIA OROZCO COYOY DE CUPIL | G16: CANTON CHUICAVIOC | H16: VIVIENDA UNIFAMILIAR | I16: 1 | K16: 1 | L16: REGULARIZACION | M16: POT. 102.35
B17: - | C17: 11 | E17: CRUCR-570226 | F17: JUANA CAHUEX CRUZ | G17: CANTON CHUICAVIOC | H17: VIVIENDA UNIFAMILIAR | I17: 1 | K17: 1 | L17: RURAL | M17: 80.39
B18: - | C18: 12 | E18: CRUCR-620226 | F18: PEDRO ROBERTO CRUZ OROZCO | G18: CANTON CHUICAVIOC | H18: VIVIENDA UNIFAMILIAR | I18: 2 | K18: 1 | L18: RURAL | M18: 130.98
B19: - | C19: 13 | E19: CRUAR-610226 | F19: JUAN RAMON AGUSTIN COYOY | G19: CANTON CHUICAVIOC | H19: VIVIENDA UNIFAMILIAR | I19: 1 | K19: 1 | L19: RURAL | M19: 215.19 ANTIGUA Y 32.56 INFORMAL
B20: 14 | C20: - | E20: RPNR11-290722 | F20: NORMA MARINA RAMOS CASTRO | G20: LOMAS DE SAN JOSE | H20: VIVIENDA UNIFAMILIAR | I20: 1 | K20: 1
B21: 15 | C21: 15 | E21: RPNL11-470922 | F21: GILBERTO ESAU LIMATUJ REYES | G21: LOMAS DE SAN JOSE | H21: VIVIENDA UNIFAMILIAR | I21: 2 | K21: 1 | L21: POT | M21: 135.06
B22: - | C22: 16 | E22: ANTNM7-240126 | F22: EDNA PATRICIA MAZARIEGOS RUIZ | G22: 9 CALLE A 0-51 ZONA 7 | H22: VIVIENDA UNIFAMILIAR | I22: 1 | K22: 1 | L22: ANTIGUA | M22: 73.78
B23: - | C23: 17 | E23: ANTNL8-220126 | F23: LIDIA ELISABETH LUCAS SANTAY | G23: 9 CALLE 0-31A INTERIOR ZONA 8 | H23: VIVIENDA UNIFAMILIAR | I23: 2 | K23: 1 | L23: ANTIGUA | M23: 179.72
B24: - | C24: 18 | E24: ANTNC3-230126 | F24: DIEGO VICTOR CHAN TEZO Y CDUEÑOS | G24: 21 AVENIDA 10-52 ZONA 3 | H24: VIVIENDA UNIFAMILIAR | I24: 1 | K24: 1 | L24: ANTIGUA | M24: 66.53
B25: 19 | C25: 19 | E25: VUNL8 | F25: LETICIA CENOVIA
B26: - | C26: 20 | E26: ANTNM3 | F26: DEMPSI ALBERTO
B27: 21 | C27: 21 | E27: VUNR3-4541225 | F27: ANGEL EUGENIO RAMON MACARIO | G27: 8 CALLE B 26-25 LOTE 49 ZONA 3 LA GRACIA | H27: LOCAL CON BODEGA
B28: 22 | C28: 22 | E28: VUNHR-220226 | F28: OTTO SELVYN HERRERA TELLO | G28: LOTE 60 MZ L FASE I XELAGARDENS | H28: VIVIENDA UNIFAMILIAR | I28: 2 | J28: 0 | K28: 1 | L28: POT | M28: 207.8 PARTE DE VIVIENDA DE DOS LOTES
B29: 23 | C29: - | E29: VUNHR-230226 | F29: OTTO SELVYN HERRERA TELLO | G29: LOTE 62 MZ L FASE I XELAGARDENS | H29: MURO PERIMETRAL | I29: - | J29: 0 | K29: 0 | L29: POT | M29: 99 M2 DE MURO PERIMETRAL
B30: 24 | C30: - | E30: DMNM1-261225 | F30: LUIS ROBERTO MOLINA POCOM | G30: 1 CALLE 21-27 ZONA 1 | H30: DEMOLICION DE VIVIENDA ANTIGUA | I30: 1 | J30: 0 | K30: 0 | L30: POT | M30: 141.28 M2 DE DEMOLICION
B31: 25 | C31: 25 | E31: VUNM1-4371225 | F31: LUIS ROBERTO MOLINA POCOM | G31: 1 CALLE 21-27 ZONA 1 | H31: VIVIENDA UNIFAMILIAR | I31: 2 | K31: 1 | L31: POT | M31: 160.91
B32: 26 | C32: 26 | E32: RPNS7-180623 | F32: JOSE LUIS SUAREZ SANTIZO | G32: 9 CALLE A 1-43 LOTE 17 SAN MARTIN ZONA 7 | H32: VIVIENDA UNIFAMILIAR | I32: 2 | K32: 1 | L32: REGULARIZACION | M32: 73.09 RECIENTE Y 35 ANTIGUA
B33: - | C33: 27 | E33: ANTNS1-1-470226
B34: 28 | C34: 28 | E34: RPNC7-2000226 | F34: MARIA CUX LOPEZ | G34: CERO AVENIDA 1-69 ZONA 7 | H34: VIVIENDA BIFAMILIAR | I34: 1 | K34: 2 | L34: POT | M34: 91.13 ANTIGUA Y 95.25 M2 CARGADOS

Sheet REPORTES
B2: REPORTES/REGULARIZACIONES
B5: NO. | C5: NO. EXPEDIENTE | D5: NOMBRE | F5: INSPECTOR
B6: 1 | C6: RPNSR-560321 | D6: ='INFORME '!#REF! -> #REF! | F6: NATALIE RIVERA
B7: 2 | C7: ='INFORME '!#REF! -> #REF! | D7: ILIANA VANESSA IXQUIAC MORALES | F7: JOSE JUAREZ
B8: 3 | C8: ='INFORME '!#REF! -> #REF! | D8: HENRY JACINTO AGUILAR RECINOS | F8: JOSE JUAREZ
B9: 4 | C9: ='INFORME '!#REF! -> #REF! | D9: ='INFORME '!#REF! -> #REF! | F9: JOSE JUAREZ
B10: 5 | C10: RPNTR-090124 | D10: ='INFORME '!#REF! -> #REF! | F10: JOSE JUAREZ
B11: 6 | C11: RPNR8-551023 | D11: JORGE MARIO RODAS LOPEZ | F11: JOSE JUAREZ
B12: 7 | C12: RPNC6-411023 | D12: HENRY FIDEL CHANCHAVAC ACABAL | F12: KAREN MORALES
B13: 8 | C13: RPNDR-100124 | D13: DESARROLLOS DE SUR OCCIDENTE S.A. LOTE E9 | F13: KAREN MORALES
B14: 9 | C14: RPNDR-130124 | D14: DESARROLLOS DE SUR OCCIDENTE S.A. LOTE E5 | F14: KAREN MORALES
B15: 10 | C15: RPNDR-120124 | D15: DESARROLLOS DE SUR OCCIDENTE S.A. LOTE E11 | F15: KAREN MORALES
B16: 11 | C16: RPNDR-110124 | D16: DESARROLLOS DE SUR OCCIDENTE S.A. LOTE E4 | F16: KAREN MORALES
B17: 12 | C17: RPNQ7-010124 | D17: DINA NOEMI QUIÑONEZ DE LA CRUZ | F17: JOSE JUAREZ
B18: 13 | C18: RPNR1-151020 | D18: EDGAR RACANCOJ GARCIA Y CDUENA | F18: LILY GOMEZ
B19: 14 | C19: RPNM1-070124 | D19: AURA CATALINA VILLATORO Y VILLATORO DE MONZON | F19: KAREN MORALES
B20: 15 | C20: RPND7-060224 | D20: ORIEL HUSAI DIAZ GRAMAJO | F20: KAREN MORALES
B21: 16 | C21: RPNLR-290124 | D21: JUANA LOPEZ LOPEZ | F21: KAREN MORALES
B22: 17 | C22: RPNS8-080224 | D22: ANA GLADIS VASQUEZ BARRIOS DE SILVESTRE | F22: KAREN MORALES
... B56: 51 | C56: RPNC1-360424 | D56: ANELVIA IRACEMA LOPEZ GONZALEZ DE CHAVEZ | F56: KAREN MORALES
B57: 52 | C57: RPNL8-220524 | D57: VICTOR EDUARDO LOPEZ ZACARIAS
B58: 53 | C58: RPNS8-180524 | D58: JULIO MARIANO SANTIZO MARTINEZ Y CONDUEÑA
B59: 54 | C59: RPNP7-130324 | D59: SAUL PEREZ Y PEREZ
B60: 55 | C60: RPNC5-370424 | D60: LEISVAN BRUMILDA MORALES DE COLOP
B61: 56 | C61: RPNL3-120224 | D61: EDWIN AROLDO LEGRAND BARRIOS
B62: 57 | C62: RPNC10-180324 | D62: DULCE FLOR DE MARIA CUPIL TUCUX
B63: 58 | C63: RPNC9-030124 | D63: MAURA ARACELY CALDERON DIAZ
B64: 59 | C64: PNRMR-1090824 | D64: JUAN MIGUEL MATUL MACARIO
B65: 60 | C65: RPNBR-1080824 | D65: JOSE ANTONIO BELETZUY LOPEZ
B66: 61 | C66: RPNH1-460424 | D66: JUAN BARTOLO HERNANDEZ POZ
B67: 62 | C67: RPNM5-560324 | D67: DIEGO RAUL MECKLER ALVAREZ
B68: 63 | C68: RPNP1-500524 | D68: ERVIN JOSE PEREZ ESCOBAR
... B70: 65 | C70: RPNCR-1511224 | D70: CARMELINA CHICHE MEJIA DE LOPEZ
B71: 66
B72: 67
B73: 68
B74: 69
B75: 70
B76: 71
B77: 72
...

Sheet JACKY
B2: NO. | C2: EXPEDIENTE | D2: ANTECEDENTES | E2: NOMBRE | F2: NOTA | G2: FECHA DE ENVIO | H2: DEPENDENCIA | I2: TIPO DE DOC
B3: 1 | C3: RPNOR-420423 | D3: I-13-0151-2022 | E3: LUIS DAVID, OCHOA LOPEZ | F3: FALTA PAGO DE MULTA Y SOLVENCIA | G3: 45019 | H3: JAM | I3: COPIA
B4: 2 | C4: RPT11-020519 | D4: I-13-0446-2019 | E4: CLAUDIA KARINA ROSALES FLORES DE TOBAR | F4: FALTA SOLVENCIA | G4: 43894 | H4: JAM | I4: COPIA
B5: 3 | C5: RPNC5-500722 | D5: I-05-0845-2022 | E5: ANA CAROLINA CARDENAS CITAN | F5: FALTA SOLVENCIA | G5: 44847 | H5: JAM | I5: COPIA
B6: 4 | C6: RPNG5-611022 | D6: I-05-1517-2021 | E6: EDNA ELIZABET DAMIAN GIRON DE GONZALEZ | F6: FALTA SOLVENCIA | G6: 45008 | H6: JAM | I6: COPIA
B7: 5 | C7: RPND6-060121 | D7: I-06-0895-2020 | E7: ERIK ANTONY DE LEON AVILA | F7: FALTA SOLVENCIA | G7: 44371 | H7: JAM | I7: COPIA
B8: 6 | C8: RPNM10-050220 | D8: I-13-1205-2019 | E8: CARLOTA MENCHU HERNANADEZ LOPEZ | F8: PENDIENTE CARGA URBANISTICA | G8: 44214 | H8: OT | I8: COPIA
B9: 7 | C9: RPNC11-420822 | D9: I-13-0471-2021 | E9: JOSEFINA ELIZABETH CHAN PEREZ | F9: FALTA SOLVENCIA | G9: 44895 | H9: JAM | I9: COPIA
B10: 8 | C10: RPNJ1-370722 | D10: I-01-1383-2021 | F10: FALTA SOLVENCIA | G10: 44916 | H10: JAM | I10: COPIA
B11: 9 | C11: RPNS5-630821 | D11: I-05-0960-2021 | E11: JULIA SAJCHE | F11: FALTA SOLVENCIA | G11: 44635 | H11: JAM | I11: COPIA
B12: 10 | C12: RPND5-560822 | D12: I-05-06-20-2022 | E12: PAOLA MERCEDES DE LEON | F12: FALTA SOLVENCIA | G12: 44895 | H12: JAM | I12: COPIA
B13: 11 | C13: RPND6-052022 | E13: ANA MARIA VELSQUEZ SIERRA | F13: FALTA SOLVENCIA | G13: 44684 | H13: JAM | I13: COPIA
B14: 12 | C14: RPPR-090319 | D14: I-13-0292-2019 | E14: ABRAHAM PAC BOJ | F14: FALTA SOLVENCIA | G14: 43844 | H14: JAM | I14: COPIA
B15: 13 | C15: RPND5-170222 | D15: I-05-1249-2022 | E15: LUDWIN ALEXANDER DE LEON RIVAS | F15: FALTA SOLVENCIA | G15: 45099 | H15: JAM | I15: COPIA
B16: 14 | C16: RPNL9-110123 | D16: I-13-1309-2021 | E16: LUDY NORBERTA LOPEZ MORENO DE GUTIERREZ | F16: FALTA SOLVENCIA | G16: 45110 | H16: JAM | I16: COPIA
B17: 15 | C17: RPND5-130323 | D17: I-05-0841-2022 | E17: MARCO AURELIO DIAZ REINA | F17: FALTA SOLVENCIA | G17: 45063 | H17: JAM | I17: COPIA
B18: 16 | C18: RPNM8-180223 | D18: I-08-0153-2023 | E18: CLAUDIA MARIA ZALDAÑA RIVERA DE MORALES | F18: FALTA SOLVENCIA | G18: 45092 | H18: JAM | I18: COPIA
B19: 17 | C19: RPNR6-070322 | D19: I-01-0093-2022 | E19: DAMIAN OVISPO RODAS LOPEZ | F19: FALTA SOLVENCIA | G19: 44714 | H19: JAM | I19: COPIA
B20: 18 | C20: RPNP3-030223 | D20: I-13-1151-2022 | E20: ELIAS ABRAHAM PEC DE LEON | F20: FALTA SOLVENCIA | G20: 45061 | H20: JAM | I20: COPIA
B21: 19 | C21: RPNC2-010222 | D21: I-02-0773-2020 | E21: MIRIAM BEATRIZ CUC TECUM | F21: FALTA SOLVENCIA | G21: 44791 | H21: JAM | I21: COPIA
B22: 20 | C22: RPNH1-721121 | D22: I-10-1429-2021 | E22: IRMA PATRICIA HERNANDEZ IXQUIAC | F22: FALTA SOLVENCIA | G22: 44602 | H22: JAM | I22: COPIA
B23: 21 | C23: RPNRR-041019 | D23: I-13-1152-2019 | E23: ELVIS GALIANO RAMIREZ MACARIO | F23: FALTA SOLVENCIA/USO DE SUELO | G23: 43878 | H23: JAM | I23: COPIA
B24: 22 | C24: RPNJR-440621 | D24: I-13-0765-2021 | E24: JOSE FRANCISCO JIMENEZ MIRANDA | F24: FALTA SOLVENCIA | G24: 44657 | H24: JAM | I24: COPIA
B25: 23 | C25: RPNC4-010122 | D25: I-13-1607-2021 | E25: PEDRO DAMASCO COTOC CACATZUM | F25: FALTA SOLVENCIA | G25: 44643 | H25: JAM | I25: COPIA
... B27: 25 | C27: RPNR11-340321 | D27: I-11-1026-2020 | E27: EVANGELINA MUÑOZ OLIVA DE RUIZ | F27: NO SE PRESENTO LA INTERESADA/SE DEVOLVIO A CATASTRO | G27: 45019 | H27: JAM | I27: COPIA
B28: 26 | C28: RPNM1-090223 | E28: VITALINA SALVADOR MORALES DE MIRANDA | F28: FALTA SOLVENCIA | G28: 45042 | H28: JAM | I28: COPIA
B29: 27 | C29: RPNR12-050221 | D29: R-12-06161-2020 | E29: SAGAS SOCIEDAD ANONIMA | F29: FALTA SOLVENCIA | G29: 44392 | H29: JAM | I29: COPIA
B30: 28 | C30: RPNL4-110822 | D30: R-04-0113-2022 | E30: EDGAR AROLDO LOPEZ MORALES | F30: FALTA SOLVENCIA | G30: 44980 | H30: JAM | I30: COPIA
B31: 29 | C31: RPNR12-040221 | D31: R-12-0160-2020 | E31: RUBILIA ELIZABETH ROSALES NORIEGA | F31: FALTA SOLVENCIA | G31: 44938 | H31: JAM | I31: COPIA
B32: 30 | C32: RPNC1-140123 | D32: R-01-0384-2022 | E32: MARIA DEL ROSARIO COTI SUM DE COJOM | F32: FALTA SOLVENCIA | G32: 45092 | H32: JAM | I32: COPIA
B33: 31 | C33: RPNP10-240621 | E33: HERBERT FERNANDO PISQUIY GUZMAN | F33: FALTA SOLVENCIA | G33: 44432 | H33: JAM | I33: COPIA
B34: 32 | C34: RPW10-411118 | E34: INDUSTRIALIZADORA DE VIVIENDAS S.A | F34: ACTUALIZAR SOLVENCIA CON CONST. CARGADA | G34: 43495 | H34: JAM | I34: COPIA
B35: 33 | C35: RPQ6-261118 | E35: ELIZABETH RAMIREZ CHAVEZ DE QUIEJ | F35: ACTUALIZAR SOLVENCIA CON CONST. CARGADA | G35: 43495 | H35: JAM | I35: COPIA
B36: 34 | C36: RPD3-100519 | D36: ANT-D3-150519 | E36: MARY NOEMI DE LEON PAREDES | F36: FALTA SOLVENCIA | G36: 43661 | H36: JAM | I36: COPIA
B37: 35 | C37: RPNC1-441022 | D37: R-01-0141-2021 | E37: BERNABE CHOXOM JOCOL | F37: FALTA SOLVENCIA | G37: 44938 | H37: JAM | I37: COPIA
B38: 36 | C38: RPC1-090519 | D38: ANT-C1-250519 | E38: HONORIA COTOM FUENTES DE CHAVEZ | F38: FALTA SOLVENCIA | G38: 43655 | H38: JAM | I38: COPIA
B39: 37 | C39: RPM5-050919 | E39: MOTOS Y AUTOS S.A | F39: FALTA SOLVENCIA | G39: 43616 | H39: JAM | I39: COPIA
B40: 38 | C40: RPNL12-060122 | D40: R-12-0216-2021 | E40: ANA ELIZABETH CARRILLO RIVERA DE LOPEZ | F40: FALTA SOLVENCIA | G40: 44672 | H40: JAM | I40: COPIA
B41: 39 | C41: RPLR-080419 | D41: R-13-0019-2019 | E41: LUISA LOPEZ Y LOPEZ DE RACANCOJ Y JORGE LUIS RACANCOJ TUCUX | F41: FALTA SOLVENCIA | G41: 43741 | H41: JAM | I41: COPIA
B42: 40 | C42: RPNR3-010122 | E42: FRANCK WALTER AARON RIOS MONTERROSO | F42: FALTA SOLVENCIA | G42: 44620 | H42: JAM | I42: COPIA
...

Sheet PROV_
B3: DATOS DEL EXPEDIENTE | I3: PROVIDENCIA
B6: NO. | C6: NO. EXPEDIENTE | D6: NOMBRE | F6: FECHA IHGRESO | G6: FECHA INSPECCION | I6: DEPENDENCIA | J6: TIPO | N6: NO.
B8: 1 | C8: I-09-0529-2023 | D8: ANA NATALIA ALEJANDRO IXCOT | F8: 45181 | G8: 45301 | I8: DRENAJES | J8: POR ZANJON
B9: 2 | C9: I-09-0887-2023 | D9: PEDRO JOSE PEREZ VASQUEZ | F9: 45211 | G9: 45219 | I9: OT | J9: ALINEACION
B10: 3 | C10: I-09-0534-2023 | D10: FIDELIA SAQUIC TUY DE FLORES | F10: 45258 | G10: 45308 | I10: OT | J10: ALINEACION Y DONACION
B11: 4 | C11: I-09-0511-2023 | D11: IRMA OFELIA IXCOT MAZARIEGOS DE ALEJANDRO | F11: 45181 | G11: 45301 | I11: OT | J11: ALINEACION
B12: 5 | C12: I-09-0515-2023 | D12: LILIA BEATRIZ LOPEZ SAQUIC | F12: 45181 | G12: 45301 | I12: OT | J12: ALINEACION
B13: 6 | C13: I-06-1124-2023 | D13: NELSON ANIBAL MENDEZ GONZALEZ | F13: 45295 | G13: 45314 | I13: GESTION DE RIESGOS | J13: POR BARRANCO EN LA PARTE POSTERIOR DEL INMUEBLE
B14: 7 | C14: ANTN-M7-020124 | D14: ALLAN FRANCISCO MORALES DE LEON | I14: IUSI | J14: CONSTRUCCION ANTIGUA
B15: 8 | C15: I-05-0361-2023 | D15: ISRAEL ELEONI LOPEZ CIFUENTES | F15: 45211 | G15: 45320 | I15: OT | J15: ALINEACION MUNICIPAL
B16: 9 | C16: RPNC9-030124 | D16: MAURA ARACELY CALDERON DIAZ | F16: 45317 | G16: 45322 | I16: DRENAJES | J16: POR ZANJON | N16: 037-2024
B17: 10 | C17: R-01-0072-2020 | D17: LAURA HILDA LOPEZ COJOM DE HUITZ | F17: 45266 | G17: 45324 | I17: OT | J17: ALINEACION MUNICIPAL | N17: 038-2024
B18: 11 | C18: I-13-0474-2023 | D18: JUAN MIGUE MATUL MACARIO | F18: 45215 | G18: 45328 | I18: OT | J18: ALINEACION MUNICIPAL | N18: 043-2024
B19: 12 | C19: I-05-1158-2023 | D19: EFRAIN AVELINO GIRON BARRIOS | F19: 45313 | G19: 45328 | I19: JAM | J19: CARGA SOBRE MARQUESINA | N19: 046-2024
B20: 13 | C20: I-08-1199-2023 | D20: JUAN HUMBERTO MONTES TUL | F20: 45313 | G20: 45320 | I20: OT | J20: CAMBIO DE SECTOR | N20: 047-2024
B21: 14 | C21: R-01-0009-2024 | D21: JUAN ALBERTO RACANCOJ ESCOBAR | F21: 45321 | G21: 45330 | I21: GESTION DE RIESGOS | J21: POR AREA DE INUNDACION | N21: 048-2024
B22: 15 | C22: i-13-0859-2023 | D22: JUSTO RUFINO RAMOS HERNANDEZ | F22: 45203 | G22: 45336 | I22: OT | J22: CAMBIO DE SECTOR | N22: 049-2024
B23: 16 | C23: RPNI1-140124 | D23: JORGE MARCELO IXQUIAC CABRERA | F23: 45321 | G23: 45335 | I23: OT | J23: USO DE SUELO NO RESIDENCIAL ORDINARIO | N23: 056-2024
B24: 17 | C24: I-13-0936-2023 | D24: JOSE ANTONIO BELETZUY LOPEZ | F24: 45233 | G24: 45338 | I24: OT | J24: POR ALINEACION MUNICIPAL | N24: 057-2024
B25: 18 | C25: VUNA3-010224 | D25: JOHANA WALESKA DE LEON DE ARGUETA Y CDNO | F25: 45337 | G25: 45342 | I25: DRENAJES | J25: POR ZONA ESPECIAL/RIO | N25: 059-2024
B26: 19 | C26: VUNV6-010224 | D26: WALTER MANUEL VICENTE TZUN | F26: 45329 | G26: 45334 | I26: OT | J26: POR ALINEACION MUNICIPAL | N26: 064-2024
B27: 20 | C27: VUNG7-010324 | D27: ENRIQUE EZEQUIEL GARCIA GOMEZ | F27: 45359 | G27: 45363 | I27: OT | J27: POR ALINEACION MUNICIPAL | N27: 070-2024
... B34: 27 | C34: ANTN-M7-411123 | D34: PETRONA MATUL OXLAJ | F34: 45247 | G34: 45376 | I34: JAM | J34: CARGA SOBRE MARQUESINA | N34: 120-2024
B35: 28 | C35: ANTN-L3-060322 | D35: TELMA ELIZABETH LOPEZ | F35: 44648 | G35: - | I35: ASESORIA JURIDICA | J35: DICTAMEN DE TELMA | N35: 122-2024
B36: 29 | C36: VUNP1-020424 | D36: GUILLERMO JACOB PEREZ REYES | F36: 45391 | G36: 45399 | I36: OT | J36: POR ALINEACION MUNICIPAL | N36: 123-2024
B37: 30 | C37: VUNT11-010324 | D37: ISABEL TORRES SONTAY | F37: 45356 | G37: 45359 | I37: OT | J37: POR CAMBIO DE SECTOR | N37: 124-2024
B38: 31 | C38: RPNL10-240424 | D38: CESAR ARMANDO LOPEZ VASQUEZ | F38: 45400 | G38: 45412 | I38: OT | J38: POR ALINEACION MUNICIPAL | N38: 129-2024
B39: 32 | C39: I-07-0488-2024 | D39: HECTOR MARIO VASQUEZ ALVAREZ | F39: 45411 | G39: 45432 | I39: OT | J39: POR ALINEACION MUNICIPAL | N39: 150-2024
B40: 33 | C40: I-13-0046-2024 | D40: JAIME NOLBERTO LOPEZ OROXOM | F40: 45404 | G40: 45428 | I40: OT | J40: POR ALINEACION MUNICIPAL
B41: 34
B42: 35
B43: 36
B44: 37
B45: 38
B46: 39
B47: 40
B48: 41
B49: 42
B50: 43
B51: 44
...

Sheet INF. EXT
C2: OFICIOS EXTERNOS
C5: NO. | D5: NO. EXPEDIENTE | E5: NOMBRE | G5: FECHA IHGRESO | H5: FECHA INSPECCION
C6: 1
C7: 2
C8: 3
C9: 4
C10: 5
C11: 6
C12: 7
C13: 8
C14: 9
C15: 10
C16: 11
C17: 12
... C54: 49
C55: 50 | D55: VUNV6-010224 | E55: WALTER MANUEL VICENTE TZUN
C56: 51
C57: 52
C58: 53
C59: 54
C60: 55
C61: 56
C62: 57
C63: 58
C64: 59
C65: 60
C66: 61
C67: 62
... C177: 172

Sheet OFICIOS
C2: OFICIOS EXTERNOS
C5: NO. | D5: NO. EXPEDIENTE | E5: NOMBRE | G5: FECHA IHGRESO | H5: FECHA INSPECCION | I5: DEPENDENCIA | J5: TIPO | M5: NUMERO INFORME | N5: FECHA QUE SE IMPRIMIO | O5: FECHA QUE SE RECIBIO
C6: 1
C7: 2
C8: 3
C9: 4
C10: 5 | D10: I-09-0511-2023 | E10: IRMA OFELIA IXCOT MAZARIEGOS DE ALEJANDRO | G10: 45181 | H10: 45301 | I10: CATAASTRO | J10: SE ANULA PORQUE NO ES PARA CATASTRO
C11: 6 | D11: I-09-0546-2023 | E11: JOVITA ALVA ACABAL VASQUEZ DE HUNTER | G11: 45258 | H11: 45308 | I11: CATASTRO | J11: INFORME POR CONSTRUCCION RURAL | M11: 084-2024 | N11: 45308
C12: 7 | D12: I-05-1142-2022 | E12: ANGELA CHAN | G12: 44868 | H12: 44942 | I12: CATASTRO | J12: INFORME POR CONSTRUCCION RURAL ANTIGUA | M12: 088-2024 | N12: 45309
C13: 8 | D13: I-01-1032-2023 | E13: MARCO ANTONIO CALVAC GUERRA | G13: 45247 | H13: 45280 | I13: CATASTRO | J13: OFICIO POR CONSTRUCCION ANTIGUA | M13: 098-2024 | N13: 45313
C14: 9 | D14: I-13-1563-2022 | E14: CAROLINA COTOM GUZMAN DE CRUZ | G14: 44949 | H14: 45282 | I14: CATASTRO | J14: INFORME POR CONSTRUCCION RURAL | M14: 102-2024 | N14: 45314
C15: 10 | D15: I-06-0302-2023 | E15: JOSUE GARCIA QUIÑONEZ | G15: 45068 | H15: 45155 | I15: CATASTRO | J15: OFICIO POR REGULARIZACION | M15: 117-2024 | N15: 45315
C16: 11 | D16: I-06-0300-2023 | E16: JOSUE GARCIA QUIÑONEZ | G16: 45068 | H16: 45155 | I16: CATASTRO | J16: OFICIO POR REGULARIZACION | M16: 118-2024 | N16: 45315
C17: 12 | D17: I-13-0790-2022 | E17: JULIA LUCIA AMBROCIO MACARIO DE MENCHU | G17: 44834 | H17: 44852 | I17: CATASTRO | J17: OFICIO POR REGULARIZACION | M17: 119-2024 | N17: 45315
C18: 13 | D18: I-13-0947-2023 | E18: NOELIA FELICIANA RUIZ ANASTASIO | G18: 45303 | H18: 45316 | I18: CATASTRO | J18: OFICIO POR CONSTRUCCION INFORMAL | M18: 130-2024 | N18: 45317
C19: 14 | D19: I-13-0826-2023 | E19: MOISES AJCA CHAJ | G19: 45181 | H19: 45245 | I19: CATASTRO | J19: OFICIO POR REGULARIZACION | M19: 141-2024 | N19: 45320
C20: 15 | D20: RPNG2-100322 | E20: JUAN JOSE GARCIA GARCIA | G20: 44631 | H20: 44756 | I20: JAM | J20: OFICIO POR EXONERACION | M20: 146-2024 | N20: 45321
C21: 16 | D21: RPNM1-070124 | E21: AURA CATALINA VILLATORO Y VILLATORO DE MONZON | G21: 45310 | H21: 45316 | I21: JAM | J21: OFICIO POR EDIFICABILIDAD | M21: 157-2024 | N21: 45323
C22: 17 | D22: I-01-1137-2023 | E22: MARIA GABRIELA ESCOBAR MOMOTIC | G22: 45282 | H22: 45324 | I22: CATASTRO | J22: OFICIO POR CONSTRUCCION ANTIGUA | M22: 165-2024 | N22: 45327
... C80: 75 | D80: R-10-0020-2024 | E80: JUAN FERNANDO MOISES HERNANDEZ QUIJIVIX | G80: 45345 | H80: 45383 | I80: CATASTRO | J80: OFICIO POR REGULARIZACION | M80: 708-2024 | N80: 45429
C81: 76 | D81: I-07-1074-2022 | E81: SUSANO ROLANDO VICENTE VICENTE | G81: 7/11//22 | H81: 44964 | I81: CATASTRO | J81: OFICIO POR REGULARIZACION | M81: 709-2024 | N81: 45429
C82: 77 | D82: I-13-0187-2024 | E82: NORMA LETICIA COYOY IXCOT DE AGUSTIN | G82: 45363 | H82: 45422 | I82: CATASTRO | J82: OFICIO POR CONTRUCCION EN PLAN REGULADOR | M82: 714-2024 | N82: 45429
C83: 78 | D83: I-13-0260-2024 | E83: ELVIA ELVIRA COYOY IXCOT | G83: 45421 | H83: 45422 | I83: CATASTRO | J83: OFICIO POR CONTRUCCION EN PLAN REGULADOR | M83: 715-2024 | N83: 45429
C84: 79 | D84: 0078-2023 | E84: CATALINA QUEME SACOR DE GOMEZ | G84: 44980 | H84: 45020 | I84: IUSI | J84: OFICIO POR REGULARIZACION DE DEMOLICION | M84: 723-2024 | N84: 45432
C85: 80 | D85: I-03-0095;6;7;8-2024 | E85: DORA MARINA RODAS HERRERA | G85: 45408 | H85: 45391 | I85: CATASTRO | J85: OFICIO POR NOMENCLATURAS ADICIONALES | M85: 740-2024 | N85: 45433
C86: 81 | D86: I-13-0104-2023 | E86: HENRY JACINTO AGUILAR RECINOS | I86: CATASTRO | J86: OFICIO POR REGULARIZACION | M86: 744-2024 | N86: 45433
C87: 82 | D87: R-01-0189-2023 | E87: ILIANA VANESSA IXQUIAC MORALES | I87: CATASTRO | J87: OFICIO POR REGULARIZACION | M87: 745-2024 | N87: 45433
C88: 83 | D88: D-06-0017-2021 | E88: BALDEMAR BAYNOY PEREZ LARIOS | I88: IUSI | J88: OFICIO POR REGULARIZACION | M88: 747-2024 | N88: 45433
C89: 84 | D89: I-01-0035-2024 | E89: METZLY ISABEL ZEPEDA ARAUZ | I89: CATASTRO | J89: OFICIO POR REGULARIZACION | M89: 748-2024 | N89: 45433
C90: 85 | D90: I-10-1300-2022 | E90: HUGO LEONEL JUAREZ IBARRA | I90: CATASTRO | J90: OFICIO POR REGULARIZACION | M90: 754-2024 | N90: 45434
C91: 86 | D91: R-01-0009-2024 | E91: JUAN ALBERTO RACANCOJ ESCOBAR | I91: CATASTRO | J91: OFICIO POR CONSTRUCCION ANTIGUA | M91: 756-2024 | N91: 45434
C92: 87 | D92: I-05-0065-2023 | E92: EDMER ANDRES GARCIA CASTELLON | I92: CATASTRO | J92: OFICIO POR REGULARIZACION | M92: 765-2024 | N92: 45435
C93: 88 | D93: R-01-0241-2023 | E93: DIVERSIFICACION DE ACTIVIDADES, SOCIEDAD ANONIMA | I93: CATASTRO | J93: OFICIO POR USO DE SUELO | M93: 770-2024 | N93: 45435
C94: 89 | D94: I-13-0232-2024 | E94: GERARDO EVARISTO ROBLERO ROBLERO | I94: CATASTRO | J94: OFICIO POR CONSTRUCCION ANTIGUA | M94: 774-2024 | N94: 45435
C95: 90 | D95: - | E95: ALCALDIA | I95: ALCALDIA | J95: - | M95: - | N95: -
C96: 91 | D96: RPNC1-360424 | E96: ANELVIA IRACEMA LOPEZ GONZALEZ DE CHAVEZ | I96: JAM | J96: INDICE DE EDIFICABILIDA Y PERM. | M96: 784-2024 | N96: 45439
C97: 92 | D97: I-013-0905-2023 | E97: EVELYN JOHANA MIJANGOS ARRIAZA DE DIAZ Y CONDUEÑO | I97: CATASTRO | J97: OFICIO POR REGULARIZACION | M97: 791-2024 | N97: 45440
C98: 93 | D98: I-13-0144-2024 | E98: JORGE GIOVANNI PEREZ MONZON | I98: CATASTRO | J98: OFICIO POR PLAN REGULADOR RURAL | M98: 793-2024 | N98: 45440
C99: 94 | D99: RPNS8-180524 | E99: JULIO MARIANO SANTIZO MARTINEZ Y CONDUEÑA | I99: JAM | J99: PERMEABILIDAD | M99: 809-2024 | N99: 45442
C100: 95 | D100: I-06-1124-2023 | E100: NELSON ANIBAL MENDEZ GONZALEZ | I100: CATASTRO | J100: OFICIO POR REGULARIZACION | M100: 816-2024 | N100: 45443
...

Sheet ARCHIVO
C2: YA SE ENVIARON A CATASTRO INFORMANDO LA REGULARIZACION | J2: EN ESPERA DE SOLVENCIA | Q2: ARCHIVADOS
B4: NO. | C4: EXPEDIENTE | D4: ANTECEDENTES | E4: NOMBRE | F4: NOTA | G4: DEPENDENCIA | H4: TIPO DE DOC | J4: NO. | K4: EXPEDIENTE | L4: ANTECEDENTES | M4: NOMBRE | N4: NOTA | O4: EN DEPARTAMENTO | Q4: NO. | R4: EXPEDIENTE | S4: NOMBRE
B5: 1 | D5: I-08-0361-2019 | E5: ANA GLADYS VASQUEZ BARRIOS DE SILVESTRE | F5: FALTA PAGO | G5: JAM | H5: ORIGINAL | J5: 1 | K5: RPNJ8-480823 | L5: D-08-0129-2022 | M5: MILEIDY ESTHER VELASQUEZ CIFUENTES DE JUAREZ | N5: FALTA CERTIFICACION | O5: COPIA | Q5: 1 | R5: RPNE12-040324 | S5: MARLON GIOVANNI ELIAS OCHOA
B6: 2 | C6: SE ENVIO PROVIDENCIA A OT | D6: I-08-1199-2023 | E6: JUAN HUMBERTO MONTES TUL | F6: FALTA PAGO | G6: JAM | H6: ORIGINAL | J6: 2 | K6: RPNS8-080224 | L6: I-08-0361-2019 | M6: ANA GLADYS VASQUEZ BARRIOS DE SILVESTRE | N6: FALTA CERTIFICACION | O6: COPIA
B7: 3 | C7: RPNG5-080124 | D7: I-05-1158-2023 | E7: EFRAIN AVELINO GIRON BARRIOS | F7: FALTA PAGO | G7: JAM | H7: ORIGINAL | J7: 3 | K7: RPND7-060224 | L7: R-07-0226-2023 | M7: ORIEL HUSAI DIAZ GRAMAJO | N7: FALTA CERTIFICACION | O7: COPIA
B8: 4 | C8: RPNT9-050124 | D8: I-09-0739-2022 | E8: ROSA ELIZABETH TOC HERNANDEZ | F8: FALTA PAGO | G8: JAM | H8: ORIGINAL | J8: 4 | K8: RPNB6-450823 | L8: I-06-0003-2022 | M8: NIDIA JUDIT FUENTES FUENTES DE BAUTISTA | N8: FALTA CERTIFICACION | O8: COPIA
B9: 5 | C9: RPNR10-080224 | D9: I-10-1093-2023 | E9: HENRY BALDEMIRO REYES PEÑA | F9: FALTA PAGO | G9: JAM | H9: ORIGINAL | J9: 5 | K9: RPNR10-080224 | L9: I-10-1093-2023 | M9: HENRY BALDEMIRO REYES PEÑA | N9: FALTA CERTIFICACION | O9: COPIA
B10: 6 | C10: RPNP3-281021 | D10: R-03-0143-2021 | E10: ILIANA SORAYA PEREZ LOPEZ | F10: FALTA CERTIFICACION DE INMUEBLE CORREGIDA | G10: JAM | H10: ORIGINAL Y COPIA | J10: 6 | K10: RPNT11-240823 | L10: R-05-0166-2023 | M10: SARA CELESTINA CAYAX TORRES DE TORRES | N10: FALTA CERTIFICACION | O10: COPIA
B11: 7 | C11: RPNR10-130224 | D11: I-10-0722-2023 | E11: MAURICIO JERONIMO RAMOS GALINDO | F11: FALTA PAGO | G11: JAM | H11: ORIGINAL | J11: 7 | K11: RPNR10-130224 | L11: I-10-0722-2023 | M11: MAURICIO JERONIMO RAMOS GALINDO | N11: FALTA CERTIFICACION | O11: COPIA
B12: 8 | C12: RPNJ10-460623 | D12: I-10-1300-2022 | E12: HUGO LEONEL JUAREZ IBARRA | F12: FALTA PAGO | G12: JAM | H12: ORIGINAL | J12: 8 | K12: RPNTR-090124 | L12: I-13-0742-2023 | M12: MARCO ANTONIO TISTOJ PEREZ | N12: FALTA CERTIFICACION | O12: COPIA
B13: 9 | C13: RPNQ2-020124 | D13: I-08-0020-2024 | E13: ANA LILIAN QUEME SACOR | F13: FALTA PAGO | G13: JAM | H13: ORIGINAL | J13: 9 | K13: RPNM3-070123 | L13: I-03-1525-2022 | M13: SANDRA VERONICA MENDOZA ALVAREZ | N13: FALTA CERTIFICACION | O13: COPIA
B14: 10 | C14: RPNG1-170124 | D14: I-13-0920-2022 | E14: ALBERTO DAMIAN GUERRA MARIN Y CONDUEÑA | F14: FALTA PAGO | G14: JAM | H14: ORIGINAL | J14: 10 | K14: RPNM5-580623 | L14: I-05-0490-2023 | M14: LAURA PILAR MATUL LEMUS DE MERIDA | N14: FALTA CERTIFICACION | O14: COPIA
B15: 11 | C15: RPNSR-550224 | D15: I-13-0029-2024 | E15: NICOLAS SACALXOT ESCOBAR | F15: FALTA PAGO | G15: JAM | H15: ORIGINAL | J15: 11 | K15: RPNL5-020124 | L15: I-05-0626-2022 | M15: WERNER ALEXANDER LOPEZ PEREZ | N15: FALTA CERTIFICACION | O15: COPIA
B16: 12 | C16: RPNS1-190324 | D16: R-01-0181-2023 | E16: KARIN YANETH SAJ MORATAYA | F16: FALTA PAGO | G16: JAM | H16: ORIGINAL | J16: 12 | K16: RPNQ2-020124 | L16: I-08-0020-2024 | M16: ANA LILIAN QUEME ESCOBAR | N16: FALTA CERTIFICACION | O16: COPIA
B17: 13 | C17: RPNH1-200324 | D17: I-01-0920-2023 | E17: SILVIA JUDITH HERNANDEZ LOPEZ | F17: FALTA PAGO | G17: JAM | H17: ORIGINAL | J17: 13 | K17: RPNSR-550224 | L17: I-13-0029-2024 | M17: NICOLAS SACALXOT ESCOBAR | N17: FALTA CERTIFICACION | O17: COPIA
... B33: 29 | C33: RPND7-341123 | D33: R-07-0199-2023 | E33: YORDAN HERALDO DE LA CRUZ MEJIA | F33: FALTA PAGO | G33: JAM | H33: ORIGINAL | J33: 29 | K33: RPNM6-160424 | L33: I-06-1124-2023 | M33: NELSON ANIBAL MENDEZ GONZALEZ | N33: FALTA PAGO | O33: COPIA
B34: 30 | C34: RPNC5-370424 | D34: I-13-0187-2024 | E34: LEISVAN BRUMILDA MORALES DE COLOP | F34: FALTA PAGO | G34: JAM | H34: ORIGINAL | J34: 30 | K34: RPNQR-710324 | L34: I-13-0823-2023 | M34: ALVARO JAVIER QUEME VELASQUEZ | O34: COPIA
B35: 31 | C35: RPNL3-120224 | D35: D-03-0102-2022 | E35: EDWIN AROLDO LEGRAND BARRIOS | F35: FALTA PAGO | G35: JAM | H35: ORIGINAL | J35: 31 | K35: RPNC5-250124 | L35: I-05-0054-2023 | M35: JOSE JAVIER CARDENAS CITAN | N35: FALTA CERTIFICACION | O35: COPIA
B36: 32 | C36: RPNBR-1080824 | D36: I-13-09236-2023 | E36: JOSE ANTONIO BELETZUY LOPEZ | F36: FALTA PAGO | G36: JAM | H36: ORIGINAL | J36: 32 | K36: RPNR3-100324 | L36: I-03-0129-2024 | M36: MARY YOLANDA RODAS HERRERA | N36: FALTA CERTIFICACION | O36: COPIA
B37: 33 | C37: RPNMR-1090824 | D37: I-13-0474-2023 | E37: JUAN MIGUEL MATUL MACARIO | F37: FALTA PAGO | G37: JAM | H37: ORIGINAL | J37: 33 | K37: RPNB6-170424 | L37: R-06-0067-2024 | M37: RENE FRANCISCO BARRENO BARRENO | N37: FALTA CERTIFICACION | O37: COPIA
B38: 34 | C38: RPNH1-460424 | D38: I-13-0269-2024 | E38: JUAN BARTOLO HERNANDEZ POZ | F38: FALTA PAGO | G38: JAM | H38: ORIGINAL | J38: 34 | K38: RPND7-341123 | L38: R-07-0199-2023 | M38: YORDAN HERALDO DE LA CRUZ MEJIA | N38: FALTA CERTIFICACION | O38: COPIA
B39: 35 | F39: FALTA PAGO | G39: JAM | H39: ORIGINAL | J39: 35 | K39: RPNGR-730424 | L39: I-13-0022-2024 | M39: EVELIO UBALDO GOMEZ ROMERO Y CONDUEÑO | N39: FALTA PAGO | O39: COPIA
B40: 36 | F40: FALTA PAGO | G40: JAM | H40: ORIGINAL | J40: 36 | K40: RPNL3-120224/USL3-050424 | L40: D-03-0102-2022 | M40: EDWIN AROLDO LEGRAND BARRIOS | N40: FALTA PAGO | O40: COPIA
B41: 37 | F41: FALTA PAGO | G41: JAM | H41: ORIGINAL | J41: 37 | K41: RPNTR-720324 | L41: I-13-0072-2024 | M41: PAULINA SIQUINA GONON DE TASEJ | N41: FALTA PAGO | O41: COPIA/
B42: 38 | F42: FALTA PAGO | G42: JAM | H42: ORIGINAL | J42: 38 | K42: RPNCR-050123 | L42: I-13-1503-2022 | M42: VITALINO CRUZ CAHUEX | N42: FALTA CERTIFICACION | O42: COPIA
B43: 39 | F43: FALTA PAGO | G43: JAM | H43: ORIGINAL | J43: 39 | K43: RPNC5-370424 | L43: I-13-0187-2024 | M43: LEISVAN BRUMILDA MORALES DE COLOP | N43: FALTA CERTIFICACION | O43: COPIA
B44: 40 | F44: FALTA PAGO | G44: JAM | H44: ORIGINAL | J44: 40 | K44: RPNBR-1080824 | L44: I-13-09236-2023 | M44: JOSE ANTONIO BELETZUY LOPEZ | N44: FALTA PAGO | O44: COPIA | P44: ORIGINAL
B45: 41 | F45: FALTA PAGO | G45: JAM | H45: ORIGINAL | J45: 41 | N45: FALTA CERTIFICACION | O45: COPIA
B46: 42 | F46: FALTA PAGO | G46: JAM | H46: ORIGINAL | J46: 42 | N46: FALTA CERTIFICACION | O46: COPIA
B47: 43 | F47: FALTA PAGO | G47: JAM | H47: ORIGINAL | J47: 43 | N47: FALTA CERTIFICACION | O47: COPIA
B48: 44 | F48: FALTA PAGO | G48: JAM | H48: ORIGINAL | J48: 44 | N48: FALTA CERTIFICACION | O48: COPIA
B49: 45 | F49: FALTA PAGO | G49: JAM | H49: ORIGINAL | J49: 45 | N49: FALTA CERTIFICACION | O49: COPIA
B50: 46 | F50: FALTA PAGO | G50: JAM | H50: ORIGINAL | J50: 46 | N50: FALTA CERTIFICACION | O50: COPIA
B51: 47 | F51: FALTA PAGO | G51: JAM | H51: ORIGINAL | J51: 47 | N51: FALTA CERTIFICACION | O51: COPIA
B52: 48 | F52: FALTA PAGO | G52: JAM | H52: ORIGINAL | J52: 48 | N52: FALTA CERTIFICACION | O52: COPIA
B53: 49 | F53: FALTA PAGO | G53: JAM | H53: ORIGINAL | J53: 49 | N53: FALTA CERTIFICACION | O53: COPIA
B54: 50 | F54: FALTA PAGO | G54: JAM | H54: ORIGINAL | J54: 50 | N54: FALTA CERTIFICACION | O54: COPIA
B55: 51 | F55: FALTA PAGO | G55: JAM | H55: ORIGINAL | J55: 51 | N55: FALTA CERTIFICACION | O55: COPIA
B56: 52 | F56: FALTA PAGO | G56: JAM | H56: ORIGINAL | J56: 52 | N56: FALTA CERTIFICACION | O56: COPIA
... B135: 131 | F135: FALTA PAGO | G135: JAM | H135: ORIGINAL | J135: 131 | N135: FALTA CERTIFICACION | O135: COPIA
...

Sheet IMP_PEND
B2: CONTROL INDIVIDUAL DE EXPEDIENTES ENERO 2024 | K2: CONTROL DE CERTIFICACIONES DE INMUEBLE
B3: NO. | C3: EXPEDIENTE | D3: PROPIETARIO SEGÚN SOLVENCIA | E3: DIRECCION SEGÚN SOLVENCIA | F3: ZONA | G3: COLONIA / CONDOMINIO | H3: OBSERVACIONES O NOTAS IMPORTANTES | K3: NO. | L3: INGRESO EXPEDIENTE | M3: EXPEDIENTE | N3: PROPIETARIO SEGÚN SOLVENCIA | O3: DIRECCION SEGÚN SOLVENCIA | P3: ZONA | Q3: COLONIA / CONDOMINIO | R3: FECHA QUE SE RECIBIO | S3: NOMBRE QUIEN LO INGRESO
B4: 1 | C4: VUNR8-030524 | D4: MARIA AMPARO PACAJA IXCOT DE ROJAS | H4: SE DEBE HACER INFORME DE PARQUEOS, NO DEBE DE TENER EN PASO A SERVIDUMBRE | K4: 1 | L4: 45225
B5: 2 | C5: RPNG9-180424 / I-09-0933-2023 | D5: ARMANDO FLORENCIO GARCIA PEREZ | H5: SE TRASLADO A JOSE PARA ENVIAR A CATASTRO JUNTO CON EL ORIGINAL | K5: 2 | L5: 45230
B6: 3 | C6: RPNL10-240424 | D6: CESAR ARMANDO LOPEZ DE VELASQUEZ | H6: SE TRASLADO A JOSE PARA TRABAJAR | K6: 3 | L6: 45216
B7: 4 | K7: 4 | L7: 45216
B8: 5 | K8: 5 | L8: 45196
B9: 6 | K9: 6 | L9: 45175
B10: 7 | K10: 7 | L10: 45232
B11: 8 | K11: 8 | L11: 45133
B12: 9 | K12: 9 | L12: 45166
B13: 10 | K13: 10 | L13: 45167
B14: 11 | K14: 11
B15: 12
B16: 13
B17: 14
B18: 15
B19: 16
B20: 17
B21: 18
B22: 19
B23: 20
B24: 21
B25: 22
B26: 23
... B45: 42
B48: TOTAL DE EXPEDIENTES TRABAJADOS | E48: 34 EXPEDIENTES | K48: TOTAL DE INSPECCIONES REALIZADAS
B52: CONTROL INDIVIDUAL DE EXPEDIENTES MARI/VACACIONES | K52: CONTROL INDIVIDUAL DE INSPECCIONES NOVIEMBRE 2023
B53: NO. | C53: EXPEDIENTE | D53: PROPIETARIO SEGÚN SOLVENCIA | E53: DIRECCION SEGÚN SOLVENCIA | F53: ZONA | G53: COLONIA / CONDOMINIO | H53: OBSERVACIONES O NOTAS IMPORTANTES | K53: NO. | L53: INGRESO EXPEDIENTE | M53: EXPEDIENTE | N53: PROPIETARIO SEGÚN SOLVENCIA | O53: DIRECCION SEGÚN SOLVENCIA | P53: ZONA | Q53: COLONIA / CONDOMINIO | R53: NO TELEFONO | S53: FECHA DE INSPECCION
B54: 1 | C54: RPNO9-190623 | D54: SILVIA BEATRIZ LOPEZ GARCIA DE OCHOA | E54: DIAGONAL 15 0-88D INTERIOR | F54: 9 | G54: - | H54: INFORME DE LICENCIA
B55: 2 | C55: RPN012-151022 | D55: WILLIAM ARNOLDO OSORIO MARTINEZ | E55: 5 CALLE 4-52 LOTE 106 MANZANA F | F55: 12 | G55: - | H55: INFORME DE LICENCIA
B56: 3 | C56: RPNT1-340723 | D56: LETICIA YOLANDA HUITZ ORDOÑEZ DE TIGUILA | E56: 11 CALLE C11D-33 | F56: 1 | G56: - | H56: INFORME DE LICENCIA
B57: 4 | C57: INF5-010922 | D57: ROSA MARIA AMBROSIO CUX | E57: 16 CALLE 7-30 | F57: 5 | G57: - | H57: INFORME INTERNO A DANI
B58: 5 | C58: USC9-020423 | D58: JUAN FRANCISCO COTOM SAQUIC | E58: 9 CALLE 4-13 INTERIOR | F58: 9 | G58: - | H58: INFORME DE LICENCIA
B59: 6 | C59: RPNC10-170223 | D59: HECTOR ARTURO CAMACHO SOLORZANO | E59: 7 AVENIDA B 0-212 | F59: 10 | G59: - | H59: INFORME DE LICENCIA
B60: 7
B61: 8
B62: 9
B63: 10
B64: 11
...

Sheet INGRESADOS
B2: CONTROL INDIVIDUAL DE EXPEDIENTES ENERO 2024 | L2: CONTROL DE CERTIFICACIONES DE INMUEBLE
B3: NO. | C3: RE-INGRESO EXPEDIENTE | D3: EXPEDIENTE | E3: PROPIETARIO SEGÚN SOLVENCIA | F3: DIRECCION SEGÚN SOLVENCIA | G3: ZONA | H3: COLONIA / CONDOMINIO | I3: OBSERVACIONES O NOTAS IMPORTANTES | L3: NO. | M3: INGRESO EXPEDIENTE | N3: EXPEDIENTE | O3: PROPIETARIO SEGÚN SOLVENCIA | P3: DIRECCION SEGÚN SOLVENCIA | Q3: ZONA | R3: COLONIA / CONDOMINIO | S3: FECHA QUE SE RECIBIO | T3: NOMBRE QUIEN LO INGRESO
B4: 1 | C4: 45313 | D4: RPNG2-060923 | E4: CATALINA QUEME SACOR DE GOMEZ | L4: 1 | M4: 45225
B5: 2 | D5: RPNP3- | E5: ILIANA SORAYA PEREZ LOPEZ | L5: 2 | M5: 45230
B6: 3 | C6: 45320 | D6: V-01-0081-2023 | E6: ARBELIO ELADIO GRAMAJO AGUILAR | F6: F:97908 F:269 L:389 | G6: 1 | H6: - | I6: INFORME POR CORRECCION DE AREA EN PLANO DE REGISTRO | L6: 3 | M6: 45216
B7: 4 | L7: 4 | M7: 45216
B8: 5 | L8: 5 | M8: 45196
B9: 6 | L9: 6 | M9: 45175
B10: 7 | L10: 7 | M10: 45232
B11: 8 | L11: 8 | M11: 45133
B12: 9 | L12: 9 | M12: 45166
B13: 10 | L13: 10 | M13: 45167
B14: 11 | L14: 11
B15: 12
B16: 13
B17: 14
B18: 15
B19: 16
B20: 17
B21: 18
B22: 19
B23: 20
B24: 21
B25: 22
B26: 23
... B45: 42
B48: TOTAL DE EXPEDIENTES TRABAJADOS | F48: 34 EXPEDIENTES | L48: TOTAL DE INSPECCIONES REALIZADAS
B52: CONTROL INDIVIDUAL DE EXPEDIENTES MARI/VACACIONES | L52: CONTROL INDIVIDUAL DE INSPECCIONES NOVIEMBRE 2023
